Workbook

Sheet لیست 
A1: رهنمود کاربرد جدول | D1: سال تعلیمی: | E1: 1404 | F1: هجري شمسي | H1: 1447 | L1: هجري قمري | N1: صنف: | P1: ( ) | S1: نگران صنف: | W1: ( ) | Z1: مکتب: | AB1: لیسه عالی ( ) | AH1: مربوط حوزه/ ولسوالی: | AM1: امریت معارف ( ) | AU1: ریاست مربوطه: | BA1: ریاست معارف ( ) | BB1: اسم و تخلص امر مکتب: | BC1: ( )
A2: https://youtu.be/7CpctKp4Fx8?si=KFc2yuxwiJChNH0C لینک ویدیو اموزشی | D2: ایام محرومی صنف مربوطه: | F2: 99 | G2: وضعیت شاگردان | H2: معذرتی | K2: بخش ثبت نمرات و ضوابط امتحان چهارونیم ماهه | AF2: بخش ثبت نمرات و ضوابط امتحان سالانه | BA2: اسم های (امر مکتب، مدیر تدریسی، سرمعلم، و هیئت سه نفری نتایج مکتب را بنوسید. | BB2: اسم و تخلص مدیر تدریسی: | BC2: ( )
A3: شماره | B3: اسم | C3: ولد | D3: ولدیت | E3: نمبر اساس | F3: نمبر تذکره | H3: چهارونیم ماهه | I3: سالانه | K3: قرانکریم | L3: دنیات | M3: دری | N3: پشتو | O3: لسان سوم | P3: انګلیسی | Q3: ریاضی | R3: ساینس | S3: اجتماعیات | T3: خط/ رسم | U3: مهارت زندگی | V3: تربیت بدنی | W3: تهذیب | X3: / | Y3: / | Z3: ایام سال تعلیمی | AA3: حاضر | AB3: غیرحاضر | AC3: مریض | AD3: رخصت | AF3: =K3 -> قرانکریم | AG3: =L3 -> دنیات | AH3: =M3 -> دری | AI3: =N3 -> پشتو | AJ3: =O3 -> لسان سوم | AK3: =P3 -> انګلیسی | AL3: =Q3 -> ریاضی | AM3: =R3 -> ساینس | ... AY3: =AD3 -> رخصت | BA3: ملاحظات شاگردان | BB3: اسم و تخلص سرمعلم مربوطه | BC3: ( )
BB4: اسم های هیئت سه نفری نتایج مکتب
A5: =ROW()-4 -> 1 | BB5: هیئت 1 | BC5: ( )
A6: =ROW()-4 -> 2
A7: =ROW()-4 -> 3 | BB7: هیئت 2 | BC7: ( )
A8: =ROW()-4 -> 4 | BB8: هیئت 3 | BC8: ( )
A9: =ROW()-4 -> 5
A10: =ROW()-4 -> 6
A11: =ROW()-4 -> 7
A12: =ROW()-4 -> 8
A13: =ROW()-4 -> 9
A14: =ROW()-4 -> 10
A15: =ROW()-4 -> 11
A16: =ROW()-4 -> 12
A17: =ROW()-4 -> 13
A18: =ROW()-4 -> 14
A19: =ROW()-4 -> 15
A20: =ROW()-4 -> 16
... A103: =ROW()-4 -> 99

Sheet شقه
A1: امضاء مدیر مکتب | H1: =AE1 -> وزارت معارف | S1: امضاء نګران | X1: امضاء مدیر مکتب | AE1: وزارت معارف | AP1: امضاء نګران
H2: =AE2 -> ریاست معارف ( ) | AE2: ='جدول نتایج '!G3 -> ریاست معارف ( )
A3: امضاء عضو نظارت | H3: =AE3 -> امریت معارف ( ) | S3: امضاء سرمعلم | X3: امضاء عضو نظارت | AE3: ='جدول نتایج '!G5 -> امریت معارف ( ) | AP3: امضاء سرمعلم
A4: =X4 -> 1447 | D4: =AA4 -> تاریخ | H4: =AE4 -> لیسه عالی ( ) | X4: ='جدول نتایج '!L8 -> 1447 | AA4: =AA5 -> تاریخ | AE4: ='جدول نتایج '!G7 -> لیسه عالی ( )
A5: =X5 -> 1404 | D5: =AA5 -> تاریخ | H5: مضمون | N5: ممتحن | P5: =AM5 -> ( ) | S5: =AP5 -> صنف: | V5: =AS5 -> امتحان: | X5: ='جدول نتایج '!H8 -> 1404 | AA5: تاریخ | AC5: ضوابط حاضری | AG5: ='جدول نتایج '!R8 -> ( ) | AK5: نگران | AM5: ='جدول نتایج '!C8 -> ( ) | AP5: صنف: | AS5: امتحان:
A7: ملاحظات | B7: مجموعه | C7: کار خانگی | D7: فعالیت صنفی | E7: تقریری/عملی | F7: تحریری | G7: شهرت | K7: شماره | M7: ملاحظات | N7: مجموعه | O7: کار خانگی | P7: فعالیت صنفی | Q7: تقریری/عملی | R7: تحریری | S7: شهرت | W7: شماره | X7: ملاحظات | Y7: ایام سال تعلیمی | Z7: رخصت | AA7: مریض | AB7: غیر حاضر | AC7: حاضر | AD7: شهرت | AH7: شماره | AJ7: ملاحظات | AK7: ایام سال تعلیمی | AL7: رخصت | AM7: مریض | AN7: غیر حاضر | AO7: حاضر | AP7: شهرت | AT7: شماره
G8: ولد | I8: اسم | S8: ولد | U8: اسم | AD8: ولد | AF8: اسم | AP8: ولد | AR8: اسم
G10: =AD10 -> 0 | I10: =AF10 -> 0 | K10: 42 | S10: =AP10 -> 0 | U10: =AR10 -> 0 | W10: 1 | AD10: ='لیست '!C46 -> 0 | AF10: ='لیست '!B46 -> 0 | AH10: 42 | AP10: ='لیست '!C5 -> 0 | AR10: ='لیست '!B5 -> 0 | AT10: 1
G11: =AD11 -> 0 | I11: =AF11 -> 0 | K11: 43 | S11: =AP11 -> 0 | U11: =AR11 -> 0 | W11: 2 | AD11: ='لیست '!C47 -> 0 | AF11: ='لیست '!B47 -> 0 | AH11: 43 | AP11: ='لیست '!C6 -> 0 | AR11: ='لیست '!B6 -> 0 | AT11: 2
G12: =AD12 -> 0 | I12: =AF12 -> 0 | K12: 44 | S12: =AP12 -> 0 | U12: =AR12 -> 0 | W12: 3 | AD12: ='لیست '!C48 -> 0 | AF12: ='لیست '!B48 -> 0 | AH12: 44 | AP12: ='لیست '!C7 -> 0 | AR12: ='لیست '!B7 -> 0 | AT12: 3
G13: =AD13 -> 0 | I13: =AF13 -> 0 | K13: 45 | S13: =AP13 -> 0 | U13: =AR13 -> 0 | W13: 4 | AD13: ='لیست '!C49 -> 0 | AF13: ='لیست '!B49 -> 0 | AH13: 45 | AP13: ='لیست '!C8 -> 0 | AR13: ='لیست '!B8 -> 0 | AT13: 4
G14: =AD14 -> 0 | I14: =AF14 -> 0 | K14: 46 | S14: =AP14 -> 0 | U14: =AR14 -> 0 | W14: 5 | AD14: ='لیست '!C50 -> 0 | AF14: ='لیست '!B50 -> 0 | AH14: 46 | AP14: ='لیست '!C9 -> 0 | AR14: ='لیست '!B9 -> 0 | AT14: 5
G15: =AD15 -> 0 | I15: =AF15 -> 0 | K15: 47 | S15: =AP15 -> 0 | U15: =AR15 -> 0 | W15: 6 | AD15: ='لیست '!C51 -> 0 | AF15: ='لیست '!B51 -> 0 | AH15: 47 | AP15: ='لیست '!C10 -> 0 | AR15: ='لیست '!B10 -> 0 | AT15: 6
G16: =AD16 -> 0 | I16: =AF16 -> 0 | K16: 48 | S16: =AP16 -> 0 | U16: =AR16 -> 0 | W16: 7 | AD16: ='لیست '!C52 -> 0 | AF16: ='لیست '!B52 -> 0 | AH16: 48 | AP16: ='لیست '!C11 -> 0 | AR16: ='لیست '!B11 -> 0 | AT16: 7
G17: =AD17 -> 0 | I17: =AF17 -> 0 | K17: 49 | S17: =AP17 -> 0 | U17: =AR17 -> 0 | W17: 8 | AD17: ='لیست '!C53 -> 0 | AF17: ='لیست '!B53 -> 0 | AH17: 49 | AP17: ='لیست '!C12 -> 0 | AR17: ='لیست '!B12 -> 0 | AT17: 8
G18: =AD18 -> 0 | I18: =AF18 -> 0 | K18: 50 | S18: =AP18 -> 0 | U18: =AR18 -> 0 | W18: 9 | AD18: ='لیست '!C54 -> 0 | AF18: ='لیست '!B54 -> 0 | AH18: 50 | AP18: ='لیست '!C13 -> 0 | AR18: ='لیست '!B13 -> 0 | AT18: 9
G19: =AD19 -> 0 | I19: =AF19 -> 0 | K19: 51 | S19: =AP19 -> 0 | U19: =AR19 -> 0 | W19: 10 | AD19: ='لیست '!C55 -> 0 | AF19: ='لیست '!B55 -> 0 | AH19: 51 | AP19: ='لیست '!C14 -> 0 | AR19: ='لیست '!B14 -> 0 | AT19: 10
G20: =AD20 -> 0 | I20: =AF20 -> 0 | K20: 52 | S20: =AP20 -> 0 | U20: =AR20 -> 0 | W20: 11 | AD20: ='لیست '!C56 -> 0 | AF20: ='لیست '!B56 -> 0 | AH20: 52 | AP20: ='لیست '!C15 -> 0 | AR20: ='لیست '!B15 -> 0 | AT20: 11
G21: =AD21 -> 0 | I21: =AF21 -> 0 | K21: 53 | S21: =AP21 -> 0 | U21: =AR21 -> 0 | W21: 12 | AD21: ='لیست '!C57 -> 0 | AF21: ='لیست '!B57 -> 0 | AH21: 53 | AP21: ='لیست '!C16 -> 0 | AR21: ='لیست '!B16 -> 0 | AT21: 12
... G50: =AD50 -> 0 | I50: =AF50 -> 0 | K50: 82 | S50: =AP50 -> 0 | U50: =AR50 -> 0 | W50: 41 | AD50: ='لیست '!C86 -> 0 | AF50: ='لیست '!B86 -> 0 | AH50: 82 | AP50: ='لیست '!C45 -> 0 | AR50: ='لیست '!B45 -> 0 | AT50: 41
A51: از روی اوراق امتحان شاگردان درج شقه هذا گردیده بدون قلم خوردگی و تراش به اداره محترم تسلیم است . | Q51: ( ) | T51: قرار شرح فوق نمرات مضمون | X51: قرار شرح فوق ضوابط حاضری امتحان ( ) از روی حاضری یومیه درج شقه هذا گردیده بدون قلم خوردگی و تراش به اداره محترم تسلیم است. امضاء نگران
B52: ( ) | E52: غایب/ محروم | J52: ( ) | L52: شامل امتحان | S52: ( ) | U52: تعداد داخله | X52: را با حاضری یومیه و عمومی تطبیق نمودیم، که از ان جمله | AH52: =AM5 -> ( ) | AK52: مایان هئیت سه نفری ضوابط حاضری امتحان ( ) صنف
X53: صحت است. | AE53: ( ) | AG53: غایب/ محروم | AJ53: ( ) | AL53: شامل امتحان | AP53: ( ) | AR53: تعداد داخله
A54: امضاء ممیز ( ) امضاء ممتحن ( ) | X54: ( ) | AA54: امضاء و اسم هیئت سوم | AE54: ( ) | AG54: امضاء و اسم هیئت دوم | AL54: ( ) | AR54: امضاء و اسم هیئت اول

Sheet جدول نتایج 
A1: امضاء نګران: | G1: وزارت معارف | T1: الف | W1: خلص نتایج چهارونیم ماهه | AA1: خلص نتایج سالانه | AI1: =$G$1 -> وزارت معارف | AY1: خلص نتایج چهارونیم ماهه | BC1: خلص نتایج سالانه | BK1: =$G$1 -> وزارت معارف | CA1: خلص نتایج چهارونیم ماهه | CE1: خلص نتایج سالانه | CM1: =$G$1 -> وزارت معارف | DC1: خلص نتایج چهارونیم ماهه | DG1: خلص نتایج سالانه | DO1: =$G$1 -> وزارت معارف | EE1: خلص نتایج چهارونیم ماهه | EI1: خلص نتایج سالانه | EQ1: =$G$1 -> وزارت معارف | FG1: خلص نتایج چهارونیم ماهه | FK1: خلص نتایج سالانه | FS1: =$G$1 -> وزارت معارف | GI1: خلص نتایج چهارونیم ماهه | GM1: خلص نتایج سالانه | GU1: =$G$1 -> وزارت معارف | HK1: خلص نتایج چهارونیم ماهه | HO1: خلص نتایج سالانه | HW1: =$G$1 -> وزارت معارف | IM1: خلص نتایج چهارونیم ماهه | IQ1: خلص نتایج سالانه | IY1: =$G$1 -> وزارت معارف | JO1: خلص نتایج چهارونیم ماهه | JS1: خلص نتایج سالانه | KA1: =$G$1 -> وزارت معارف | KQ1: خلص نتایج چهارونیم ماهه | KU1: خلص نتایج سالانه | LC1: =$G$1 -> وزارت معارف | LS1: خلص نتایج چهارونیم ماهه | LW1: خلص نتایج سالانه | ME1: =$G$1 -> وزارت معارف | MU1: خلص نتایج چهارونیم ماهه | MY1: خلص نتایج سالانه | NG1: =$G$1 -> وزارت معارف | NW1: خلص نتایج چهارونیم ماهه | OA1: خلص نتایج سالانه
T2: ب | W2: تعداد داخله | Y2: =COUNTIF(13:13,"*")-2 -> 0 | AA2: تعداد داخله | AC2: =COUNTIF(13:13,"*")-2 -> 0 | AY2: تعداد داخله | BA2: =$Y$2 -> 0 | BC2: تعداد داخله | BE2: =$AC$2 -> 0 | CA2: تعداد داخله | CC2: =$Y$2 -> 0 | CE2: تعداد داخله | CG2: =$AC$2 -> 0 | DC2: تعداد داخله | DE2: =$Y$2 -> 0 | DG2: تعداد داخله | DI2: =$AC$2 -> 0 | EE2: تعداد داخله | EG2: =$Y$2 -> 0 | EI2: تعداد داخله | EK2: =$AC$2 -> 0 | FG2: تعداد داخله | FI2: =$Y$2 -> 0 | FK2: تعداد داخله | FM2: =$AC$2 -> 0 | GI2: تعداد داخله | GK2: =$Y$2 -> 0 | GM2: تعداد داخله | GO2: =$AC$2 -> 0 | HK2: تعداد داخله | HM2: =$Y$2 -> 0 | HO2: تعداد داخله | HQ2: =$AC$2 -> 0 | IM2: تعداد داخله | IO2: =$Y$2 -> 0 | IQ2: تعداد داخله | IS2: =$AC$2 -> 0 | JO2: تعداد داخله | JQ2: =$Y$2 -> 0 | JS2: تعداد داخله | JU2: =$AC$2 -> 0 | KQ2: تعداد داخله | KS2: =$Y$2 -> 0 | KU2: تعداد داخله | KW2: =$AC$2 -> 0 | LS2: تعداد داخله | LU2: =$Y$2 -> 0 | LW2: تعداد داخله | LY2: =$AC$2 -> 0 | MU2: تعداد داخله | MW2: =$Y$2 -> 0 | MY2: تعداد داخله | NA2: =$AC$2 -> 0 | NW2: تعداد داخله | NY2: =$Y$2 -> 0 | OA2: تعداد داخله | OC2: =$AC$2 -> 0
G3: ='لیست '!BA1 -> ریاست معارف ( ) | T3: ج | W3: شامل امتحان | Y3: =Y2-Y7 -> 0 | AA3: شامل امتحان | AC3: =AC2-AC8 -> 0 | AI3: =$G$3 -> ریاست معارف ( ) | AY3: شامل امتحان | BA3: =$Y$3 -> 0 | BC3: شامل امتحان | BE3: =$AC$3 -> 0 | BK3: =$G$3 -> ریاست معارف ( ) | CA3: شامل امتحان | CC3: =$Y$3 -> 0 | CE3: شامل امتحان | CG3: =$AC$3 -> 0 | CM3: =$G$3 -> ریاست معارف ( ) | DC3: شامل امتحان | DE3: =$Y$3 -> 0 | DG3: شامل امتحان | DI3: =$AC$3 -> 0 | DO3: =$G$3 -> ریاست معارف ( ) | EE3: شامل امتحان | EG3: =$Y$3 -> 0 | EI3: شامل امتحان | EK3: =$AC$3 -> 0 | EQ3: =$G$3 -> ریاست معارف ( ) | FG3: شامل امتحان | FI3: =$Y$3 -> 0 | FK3: شامل امتحان | FM3: =$AC$3 -> 0 | FS3: =$G$3 -> ریاست معارف ( ) | GI3: شامل امتحان | GK3: =$Y$3 -> 0 | GM3: شامل امتحان | GO3: =$AC$3 -> 0 | GU3: =$G$3 -> ریاست معارف ( ) | HK3: شامل امتحان | HM3: =$Y$3 -> 0 | HO3: شامل امتحان | HQ3: =$AC$3 -> 0 | HW3: =$G$3 -> ریاست معارف ( ) | IM3: شامل امتحان | IO3: =$Y$3 -> 0 | IQ3: شامل امتحان | IS3: =$AC$3 -> 0 | IY3: =$G$3 -> ریاست معارف ( ) | JO3: شامل امتحان | JQ3: =$Y$3 -> 0 | JS3: شامل امتحان | JU3: =$AC$3 -> 0 | KA3: =$G$3 -> ریاست معارف ( ) | KQ3: شامل امتحان | KS3: =$Y$3 -> 0 | KU3: شامل امتحان | KW3: =$AC$3 -> 0 | LC3: =$G$3 -> ریاست معارف ( ) | LS3: شامل امتحان | LU3: =$Y$3 -> 0 | LW3: شامل امتحان | LY3: =$AC$3 -> 0 | ME3: =$G$3 -> ریاست معارف ( ) | MU3: شامل امتحان | MW3: =$Y$3 -> 0 | MY3: شامل امتحان | NA3: =$AC$3 -> 0 | NG3: =$G$3 -> ریاست معارف ( ) | NW3: شامل امتحان | NY3: =$Y$3 -> 0 | OA3: شامل امتحان | OC3: =$AC$3 -> 0
A4: امضاء سرمعلم: | T4: د | W4: موفق | Y4: =COUNTIF(38:38,"موفق") -> 0 | AA4: ارتقا صنف | AC4: =COUNTIF(38:38,"ارتقا صنف") -> 0 | AY4: موفق | BA4: =$Y$4 -> 0 | BC4: ارتقا صنف | BE4: =$AC$4 -> 0 | CA4: موفق | CC4: =$Y$4 -> 0 | CE4: ارتقا صنف | CG4: =$AC$4 -> 0 | DC4: موفق | DE4: =$Y$4 -> 0 | DG4: ارتقا صنف | DI4: =$AC$4 -> 0 | EE4: موفق | EG4: =$Y$4 -> 0 | EI4: ارتقا صنف | EK4: =$AC$4 -> 0 | FG4: موفق | FI4: =$Y$4 -> 0 | FK4: ارتقا صنف | FM4: =$AC$4 -> 0 | GI4: موفق | GK4: =$Y$4 -> 0 | GM4: ارتقا صنف | GO4: =$AC$4 -> 0 | HK4: موفق | HM4: =$Y$4 -> 0 | HO4: ارتقا صنف | HQ4: =$AC$4 -> 0 | IM4: موفق | IO4: =$Y$4 -> 0 | IQ4: ارتقا صنف | IS4: =$AC$4 -> 0 | JO4: موفق | JQ4: =$Y$4 -> 0 | JS4: ارتقا صنف | JU4: =$AC$4 -> 0 | KQ4: موفق | KS4: =$Y$4 -> 0 | KU4: ارتقا صنف | KW4: =$AC$4 -> 0 | LS4: موفق | LU4: =$Y$4 -> 0 | LW4: ارتقا صنف | LY4: =$AC$4 -> 0 | MU4: موفق | MW4: =$Y$4 -> 0 | MY4: ارتقا صنف | NA4: =$AC$4 -> 0 | NW4: موفق | NY4: =$Y$4 -> 0 | OA4: ارتقا صنف | OC4: =$AC$4 -> 0
G5: ='لیست '!AM1 -> امریت معارف ( ) | T5: هـ | W5: تلاش بیشتر | Y5: =COUNTIF(38:38,"تلاش بیشتر") -> 0 | AA5: تکرار صنف | AC5: =COUNTIF(38:38,"تکرار صنف") -> 0 | AI5: =$G$5 -> امریت معارف ( ) | AY5: تلاش بیشتر | BA5: =$Y$5 -> 0 | BC5: تکرار صنف | BE5: =$AC$5 -> 0 | BK5: =$G$5 -> امریت معارف ( ) | CA5: تلاش بیشتر | CC5: =$Y$5 -> 0 | CE5: تکرار صنف | CG5: =$AC$5 -> 0 | CM5: =$G$5 -> امریت معارف ( ) | DC5: تلاش بیشتر | DE5: =$Y$5 -> 0 | DG5: تکرار صنف | DI5: =$AC$5 -> 0 | DO5: =$G$5 -> امریت معارف ( ) | EE5: تلاش بیشتر | EG5: =$Y$5 -> 0 | EI5: تکرار صنف | EK5: =$AC$5 -> 0 | EQ5: =$G$5 -> امریت معارف ( ) | FG5: تلاش بیشتر | FI5: =$Y$5 -> 0 | FK5: تکرار صنف | FM5: =$AC$5 -> 0 | FS5: =$G$5 -> امریت معارف ( ) | GI5: تلاش بیشتر | GK5: =$Y$5 -> 0 | GM5: تکرار صنف | GO5: =$AC$5 -> 0 | GU5: =$G$5 -> امریت معارف ( ) | HK5: تلاش بیشتر | HM5: =$Y$5 -> 0 | HO5: تکرار صنف | HQ5: =$AC$5 -> 0 | HW5: =$G$5 -> امریت معارف ( ) | IM5: تلاش بیشتر | IO5: =$Y$5 -> 0 | IQ5: تکرار صنف | IS5: =$AC$5 -> 0 | IY5: =$G$5 -> امریت معارف ( ) | JO5: تلاش بیشتر | JQ5: =$Y$5 -> 0 | JS5: تکرار صنف | JU5: =$AC$5 -> 0 | KA5: =$G$5 -> امریت معارف ( ) | KQ5: تلاش بیشتر | KS5: =$Y$5 -> 0 | KU5: تکرار صنف | KW5: =$AC$5 -> 0 | LC5: =$G$5 -> امریت معارف ( ) | LS5: تلاش بیشتر | LU5: =$Y$5 -> 0 | LW5: تکرار صنف | LY5: =$AC$5 -> 0 | ME5: =$G$5 -> امریت معارف ( ) | MU5: تلاش بیشتر | MW5: =$Y$5 -> 0 | MY5: تکرار صنف | NA5: =$AC$5 -> 0 | NG5: =$G$5 -> امریت معارف ( ) | NW5: تلاش بیشتر | NY5: =$Y$5 -> 0 | OA5: تکرار صنف | OC5: =$AC$5 -> 0
W6: معذ رتی | Y6: =COUNTIF(38:38,"معذرتي") -> 0 | AA6: مشروط | AC6: =COUNTIF(38:38,"مشروط") -> 0 | AY6: معذرتی | BA6: =$Y$6 -> 0 | BC6: مشروط | BE6: =$AC$6 -> 0 | CA6: معذرتی | CC6: =$Y$6 -> 0 | CE6: مشروط | CG6: =$AC$6 -> 0 | DC6: معذرتی | DE6: =$Y$6 -> 0 | DG6: مشروط | DI6: =$AC$6 -> 0 | EE6: معذرتی | EG6: =$Y$6 -> 0 | EI6: مشروط | EK6: =$AC$6 -> 0 | FG6: معذرتی | FI6: =$Y$6 -> 0 | FK6: مشروط | FM6: =$AC$6 -> 0 | GI6: معذرتی | GK6: =$Y$6 -> 0 | GM6: مشروط | GO6: =$AC$6 -> 0 | HK6: معذرتی | HM6: =$Y$6 -> 0 | HO6: مشروط | HQ6: =$AC$6 -> 0 | IM6: معذرتی | IO6: =$Y$6 -> 0 | IQ6: مشروط | IS6: =$AC$6 -> 0 | JO6: معذرتی | JQ6: =$Y$6 -> 0 | JS6: مشروط | JU6: =$AC$6 -> 0 | KQ6: معذرتی | KS6: =$Y$6 -> 0 | KU6: مشروط | KW6: =$AC$6 -> 0 | LS6: معذرتی | LU6: =$Y$6 -> 0 | LW6: مشروط | LY6: =$AC$6 -> 0 | MU6: معذرتی | MW6: =$Y$6 -> 0 | MY6: مشروط | NA6: =$AC$6 -> 0 | NW6: معذرتی | NY6: =$Y$6 -> 0 | OA6: مشروط | OC6: =$AC$6 -> 0
G7: ='لیست '!AB1 -> لیسه عالی ( ) | W7: غایب | Y7: =COUNTIF(38:38,"غایب") -> 0 | AA7: معذرتی | AC7: =COUNTIF(38:38,"معذرتی") -> 0 | AI7: =$G$7 -> لیسه عالی ( ) | AY7: غایب | BA7: =$Y$7 -> 0 | BC7: معذرتی | BE7: =$AC$7 -> 0 | BK7: =$G$7 -> لیسه عالی ( ) | CA7: غایب | CC7: =$Y$7 -> 0 | CE7: معذرتی | CG7: =$AC$7 -> 0 | CM7: =$G$7 -> لیسه عالی ( ) | DC7: غایب | DE7: =$Y$7 -> 0 | DG7: معذرتی | DI7: =$AC$7 -> 0 | DO7: =$G$7 -> لیسه عالی ( ) | EE7: غایب | EG7: =$Y$7 -> 0 | EI7: معذرتی | EK7: =$AC$7 -> 0 | EQ7: =$G$7 -> لیسه عالی ( ) | FG7: غایب | FI7: =$Y$7 -> 0 | FK7: معذرتی | FM7: =$AC$7 -> 0 | FS7: =$G$7 -> لیسه عالی ( ) | GI7: غایب | GK7: =$Y$7 -> 0 | GM7: معذرتی | GO7: =$AC$7 -> 0 | GU7: =$G$7 -> لیسه عالی ( ) | HK7: غایب | HM7: =$Y$7 -> 0 | HO7: معذرتی | HQ7: =$AC$7 -> 0 | HW7: =$G$7 -> لیسه عالی ( ) | IM7: غایب | IO7: =$Y$7 -> 0 | IQ7: معذرتی | IS7: =$AC$7 -> 0 | IY7: =$G$7 -> لیسه عالی ( ) | JO7: غایب | JQ7: =$Y$7 -> 0 | JS7: معذرتی | JU7: =$AC$7 -> 0 | KA7: =$G$7 -> لیسه عالی ( ) | KQ7: غایب | KS7: =$Y$7 -> 0 | KU7: معذرتی | KW7: =$AC$7 -> 0 | LC7: =$G$7 -> لیسه عالی ( ) | LS7: غایب | LU7: =$Y$7 -> 0 | LW7: معذرتی | LY7: =$AC$7 -> 0 | ME7: =$G$7 -> لیسه عالی ( ) | MU7: غایب | MW7: =$Y$7 -> 0 | MY7: معذرتی | NA7: =$AC$7 -> 0 | NG7: =$G$7 -> لیسه عالی ( ) | NW7: غایب | NY7: =$Y$7 -> 0 | OA7: معذرتی | OC7: =$AC$7 -> 0
A8: صنف: | C8: ='لیست '!P1 -> ( ) | E8: سال تعلیمی: | H8: ='لیست '!E1 -> 1404 | J8: هـ ش | K8: ــ | L8: ='لیست '!H1 -> 1447 | N8: هـ ق | O8: نګران صنف: | R8: ='لیست '!W1 -> ( ) | AA8: محروم | AC8: =COUNTIF(38:38,"محروم")+COUNTIF(38:38,"سه پارچه") -> 0 | AE8: =$C$8 -> ( ) | AG8: سال تعلیمی: | AJ8: =$H$8 -> 1404 | AL8: هـ ش | AM8: ــ | AN8: =$L$8 -> 1447 | AP8: هـ ق | AQ8: نګران صنف: | AT8: =$R$8 -> ( ) | BC8: محروم | BE8: =$AC$8 -> 0 | BG8: =$C$8 -> ( ) | BI8: سال تعلیمی: | BL8: =$H$8 -> 1404 | BN8: هـ ش | BO8: ــ | BP8: =$L$8 -> 1447 | BR8: هـ ق | BS8: نګران صنف: | BV8: =$R$8 -> ( ) | CE8: محروم | CG8: =$AC$8 -> 0 | CI8: =$C$8 -> ( ) | CK8: سال تعلیمی: | CN8: =$H$8 -> 1404 | CP8: هـ ش | CQ8: ــ | CR8: =$L$8 -> 1447 | CT8: هـ ق | CU8: نګران صنف: | CX8: =$R$8 -> ( ) | DG8: محروم | DI8: =$AC$8 -> 0 | DK8: =$C$8 -> ( ) | DM8: سال تعلیمی: | DP8: =$H$8 -> 1404 | DR8: هـ ش | DS8: ــ | DT8: =$L$8 -> 1447 | DV8: هـ ق | DW8: نګران صنف: | DZ8: =$R$8 -> ( ) | EI8: محروم | EK8: =$AC$8 -> 0 | EM8: =$C$8 -> ( ) | EO8: سال تعلیمی: | ER8: =$H$8 -> 1404 | ET8: هـ ش | EU8: ــ | EV8: =$L$8 -> 1447 | EX8: هـ ق | EY8: نګران صنف: | FB8: =$R$8 -> ( ) | FK8: محروم | FM8: =$AC$8 -> 0 | FO8: =$C$8 -> ( ) | FQ8: سال تعلیمی: | FT8: =$H$8 -> 1404 | FV8: هـ ش | FW8: ــ | FX8: =$L$8 -> 1447 | FZ8: هـ ق | GA8: نګران صنف: | GD8: =$R$8 -> ( ) | GM8: محروم | GO8: =$AC$8 -> 0 | GQ8: =$C$8 -> ( ) | GS8: سال تعلیمی: | GV8: =$H$8 -> 1404 | GX8: هـ ش | GY8: ــ | GZ8: =$L$8 -> 1447 | HB8: هـ ق | HC8: نګران صنف: | HF8: =$R$8 -> ( ) | HO8: محروم | HQ8: =$AC$8 -> 0 | HS8: =$C$8 -> ( ) | HU8: سال تعلیمی: | HX8: =$H$8 -> 1404 | HZ8: هـ ش | IA8: ــ | IB8: =$L$8 -> 1447 | ID8: هـ ق | IE8: نګران صنف: | IH8: =$R$8 -> ( ) | IQ8: محروم | IS8: =$AC$8 -> 0 | IU8: =$C$8 -> ( ) | IW8: سال تعلیمی: | IZ8: =$H$8 -> 1404 | JB8: هـ ش | JC8: ــ | JD8: =$L$8 -> 1447 | JF8: هـ ق | JG8: نګران صنف: | JJ8: =$R$8 -> ( ) | JS8: محروم | JU8: =$AC$8 -> 0 | JW8: =$C$8 -> ( ) | JY8: سال تعلیمی: | KB8: =$H$8 -> 1404 | KD8: هـ ش | KE8: ــ | KF8: =$L$8 -> 1447 | KH8: هـ ق | KI8: نګران صنف: | KL8: =$R$8 -> ( ) | KU8: محروم | KW8: =$AC$8 -> 0 | KY8: =$C$8 -> ( ) | LA8: سال تعلیمی: | LD8: =$H$8 -> 1404 | LF8: هـ ش | LG8: ــ | LH8: =$L$8 -> 1447 | LJ8: هـ ق | LK8: نګران صنف: | LN8: =$R$8 -> ( ) | LW8: محروم | LY8: =$AC$8 -> 0 | MA8: =$C$8 -> ( ) | MC8: سال تعلیمی: | MF8: =$H$8 -> 1404 | MH8: هـ ش | MI8: ــ | MJ8: =$L$8 -> 1447 | ML8: هـ ق | MM8: نګران صنف: | MP8: =$R$8 -> ( ) | MY8: محروم | NA8: =$AC$8 -> 0 | NC8: =$C$8 -> ( ) | NE8: سال تعلیمی: | NH8: =$H$8 -> 1404 | NJ8: هـ ش | NK8: ــ | NL8: =$L$8 -> 1447 | NN8: هـ ق | NO8: نګران صنف: | NR8: =$R$8 -> ( ) | OA8: محروم | OC8: =$AC$8 -> 0
E9: ='لیست '!F2 -> 99 | I9: =$E$9 -> 99 | M9: =$E$9 -> 99 | Q9: =$E$9 -> 99 | U9: =$E$9 -> 99 | Y9: =$E$9 -> 99 | AC9: =$E$9 -> 99 | AG9: =$E$9 -> 99 | AK9: =$E$9 -> 99 | AO9: =$E$9 -> 99 | AS9: =$E$9 -> 99 | AW9: =$E$9 -> 99 | BA9: =$E$9 -> 99 | BE9: =$E$9 -> 99 | BI9: =$E$9 -> 99 | BM9: =$E$9 -> 99 | BQ9: =$E$9 -> 99 | BU9: =$E$9 -> 99 | BY9: =$E$9 -> 99 | CC9: =$E$9 -> 99 | CG9: =$E$9 -> 99 | CK9: =$E$9 -> 99 | CO9: =$E$9 -> 99 | CS9: =$E$9 -> 99 | CW9: =$E$9 -> 99 | DA9: =$E$9 -> 99 | DE9: =$E$9 -> 99 | DI9: =$E$9 -> 99 | DM9: =$E$9 -> 99 | DQ9: =$E$9 -> 99 | DU9: =$E$9 -> 99 | DY9: =$E$9 -> 99 | EC9: =$E$9 -> 99 | EG9: =$E$9 -> 99 | EK9: =$E$9 -> 99 | EO9: =$E$9 -> 99 | ES9: =$E$9 -> 99 | EW9: =$E$9 -> 99 | FA9: =$E$9 -> 99 | FE9: =$E$9 -> 99 | FI9: =$E$9 -> 99 | FM9: =$E$9 -> 99 | FQ9: =$E$9 -> 99 | FU9: =$E$9 -> 99 | FY9: =$E$9 -> 99 | GC9: =$E$9 -> 99 | GG9: =$E$9 -> 99 | GK9: =$E$9 -> 99 | GO9: =$E$9 -> 99 | GS9: =$E$9 -> 99 | GW9: =$E$9 -> 99 | HA9: =$E$9 -> 99 | HE9: =$E$9 -> 99 | HI9: =$E$9 -> 99 | HM9: =$E$9 -> 99 | HQ9: =$E$9 -> 99 | HU9: =$E$9 -> 99 | HY9: =$E$9 -> 99 | IC9: =$E$9 -> 99 | IG9: =$E$9 -> 99 | IK9: =$E$9 -> 99 | IO9: =$E$9 -> 99 | IS9: =$E$9 -> 99 | IW9: =$E$9 -> 99 | JA9: =$E$9 -> 99 | JE9: =$E$9 -> 99 | JI9: =$E$9 -> 99 | JM9: =$E$9 -> 99 | JQ9: =$E$9 -> 99 | JU9: =$E$9 -> 99 | JY9: =$E$9 -> 99 | KC9: =$E$9 -> 99 | KG9: =$E$9 -> 99 | KK9: =$E$9 -> 99 | KO9: =$E$9 -> 99 | KS9: =$E$9 -> 99 | KW9: =$E$9 -> 99 | LA9: =$E$9 -> 99 | LE9: =$E$9 -> 99 | LI9: =$E$9 -> 99 | LM9: =$E$9 -> 99 | LQ9: =$E$9 -> 99 | LU9: =$E$9 -> 99 | LY9: =$E$9 -> 99 | MC9: =$E$9 -> 99 | MG9: =$E$9 -> 99 | MK9: =$E$9 -> 99 | MO9: =$E$9 -> 99 | MS9: =$E$9 -> 99 | MW9: =$E$9 -> 99 | NA9: =$E$9 -> 99 | NE9: =$E$9 -> 99 | NI9: =$E$9 -> 99 | NM9: =$E$9 -> 99 | NQ9: =$E$9 -> 99 | NU9: =$E$9 -> 99 | NY9: =$E$9 -> 99 | OC9: =$E$9 -> 99
C10: ='لیست '!H5 -> 0 | E10: ='لیست '!I5 -> 0 | G10: ='لیست '!H6 -> 0 | I10: ='لیست '!I6 -> 0 | K10: ='لیست '!H7 -> 0 | M10: ='لیست '!I7 -> 0 | O10: ='لیست '!H8 -> 0 | Q10: ='لیست '!I8 -> 0 | S10: ='لیست '!H9 -> 0 | U10: ='لیست '!I9 -> 0 | W10: ='لیست '!H10 -> 0 | Y10: ='لیست '!I10 -> 0 | AA10: ='لیست '!H11 -> 0 | AC10: ='لیست '!I11 -> 0 | AE10: ='لیست '!H12 -> 0 | AG10: ='لیست '!I12 -> 0 | AI10: ='لیست '!H13 -> 0 | AK10: ='لیست '!I13 -> 0 | AM10: ='لیست '!H14 -> 0 | AO10: ='لیست '!I14 -> 0 | AQ10: ='لیست '!H15 -> 0 | AS10: ='لیست '!I15 -> 0 | AU10: ='لیست '!H16 -> 0 | AW10: ='لیست '!I16 -> 0 | AY10: ='لیست '!H17 -> 0 | BA10: ='لیست '!I17 -> 0 | BC10: ='لیست '!H18 -> 0 | BE10: ='لیست '!I18 -> 0 | BG10: ='لیست '!H19 -> 0 | BI10: ='لیست '!I19 -> 0 | BK10: ='لیست '!H20 -> 0 | BM10: ='لیست '!I20 -> 0 | BO10: ='لیست '!H21 -> 0 | BQ10: ='لیست '!I21 -> 0 | BS10: ='لیست '!H22 -> 0 | BU10: ='لیست '!I22 -> 0 | BW10: ='لیست '!H23 -> 0 | BY10: ='لیست '!I23 -> 0 | CA10: ='لیست '!H24 -> 0 | CC10: ='لیست '!I24 -> 0 | CE10: ='لیست '!H25 -> 0 | CG10: ='لیست '!I25 -> 0 | CI10: ='لیست '!H26 -> 0 | CK10: ='لیست '!I26 -> 0 | CM10: ='لیست '!H27 -> 0 | CO10: ='لیست '!I27 -> 0 | CQ10: ='لیست '!H28 -> 0 | CS10: ='لیست '!I28 -> 0 | CU10: ='لیست '!H29 -> 0 | CW10: ='لیست '!I29 -> 0 | CY10: ='لیست '!H30 -> 0 | DA10: ='لیست '!I30 -> 0 | DC10: ='لیست '!H31 -> 0 | DE10: ='لیست '!I31 -> 0 | DG10: ='لیست '!H32 -> 0 | DI10: ='لیست '!I32 -> 0 | DK10: ='لیست '!H33 -> 0 | DM10: ='لیست '!I33 -> 0 | DO10: ='لیست '!H34 -> 0 | DQ10: ='لیست '!I34 -> 0 | DS10: ='لیست '!H35 -> 0 | DU10: ='لیست '!I35 -> 0 | DW10: ='لیست '!H36 -> 0 | DY10: ='لیست '!I36 -> 0 | EA10: ='لیست '!H37 -> 0 | EC10: ='لیست '!I37 -> 0 | EE10: ='لیست '!H38 -> 0 | EG10: ='لیست '!I38 -> 0 | EI10: ='لیست '!H39 -> 0 | EK10: ='لیست '!I39 -> 0 | EM10: ='لیست '!H40 -> 0 | EO10: ='لیست '!I40 -> 0 | EQ10: ='لیست '!H41 -> 0 | ES10: ='لیست '!I41 -> 0 | EU10: ='لیست '!H42 -> 0 | EW10: ='لیست '!I42 -> 0 | EY10: ='لیست '!H43 -> 0 | FA10: ='لیست '!I43 -> 0 | FC10: ='لیست '!H44 -> 0 | FE10: ='لیست '!I44 -> 0 | FG10: ='لیست '!H45 -> 0 | FI10: ='لیست '!I45 -> 0 | FK10: ='لیست '!H46 -> 0 | FM10: ='لیست '!I46 -> 0 | FO10: ='لیست '!H47 -> 0 | FQ10: ='لیست '!I47 -> 0 | FS10: ='لیست '!H48 -> 0 | FU10: ='لیست '!I48 -> 0 | FW10: ='لیست '!H49 -> 0 | FY10: ='لیست '!I49 -> 0 | GA10: ='لیست '!H50 -> 0 | GC10: ='لیست '!I50 -> 0 | GE10: ='لیست '!H51 -> 0 | GG10: ='لیست '!I51 -> 0 | GI10: ='لیست '!H52 -> 0 | GK10: ='لیست '!I52 -> 0 | GM10: ='لیست '!H53 -> 0 | GO10: ='لیست '!I53 -> 0 | GQ10: ='لیست '!H54 -> 0 | GS10: ='لیست '!I54 -> 0 | GU10: ='لیست '!H55 -> 0 | GW10: ='لیست '!I55 -> 0 | GY10: ='لیست '!H56 -> 0 | HA10: ='لیست '!I56 -> 0 | HC10: ='لیست '!H57 -> 0 | HE10: ='لیست '!I57 -> 0 | HG10: ='لیست '!H58 -> 0 | HI10: ='لیست '!I58 -> 0 | HK10: ='لیست '!H59 -> 0 | HM10: ='لیست '!I59 -> 0 | HO10: ='لیست '!H60 -> 0 | HQ10: ='لیست '!I60 -> 0 | HS10: ='لیست '!H61 -> 0 | HU10: ='لیست '!I61 -> 0 | HW10: ='لیست '!H62 -> 0 | HY10: ='لیست '!I62 -> 0 | IA10: ='لیست '!H63 -> 0 | IC10: ='لیست '!I63 -> 0 | IE10: ='لیست '!H64 -> 0 | IG10: ='لیست '!I64 -> 0 | II10: ='لیست '!H65 -> 0 | IK10: ='لیست '!I65 -> 0 | IM10: ='لیست '!H66 -> 0 | IO10: ='لیست '!I66 -> 0 | IQ10: ='لیست '!H67 -> 0 | IS10: ='لیست '!I67 -> 0 | IU10: ='لیست '!H68 -> 0 | IW10: ='لیست '!I68 -> 0 | IY10: ='لیست '!H69 -> 0 | JA10: ='لیست '!I69 -> 0 | JC10: ='لیست '!H70 -> 0 | JE10: ='لیست '!I70 -> 0 | JG10: ='لیست '!H71 -> 0 | JI10: ='لیست '!I71 -> 0 | JK10: ='لیست '!H72 -> 0 | JM10: ='لیست '!I72 -> 0 | JO10: ='لیست '!H73 -> 0 | JQ10: ='لیست '!I73 -> 0 | JS10: ='لیست '!H74 -> 0 | JU10: ='لیست '!I74 -> 0 | JW10: ='لیست '!H75 -> 0 | JY10: ='لیست '!I75 -> 0 | KA10: ='لیست '!H76 -> 0 | KC10: ='لیست '!I76 -> 0 | KE10: ='لیست '!H77 -> 0 | KG10: ='لیست '!I77 -> 0 | KI10: ='لیست '!H78 -> 0 | KK10: ='لیست '!I78 -> 0 | KM10: ='لیست '!H79 -> 0 | KO10: ='لیست '!I79 -> 0 | KQ10: ='لیست '!H80 -> 0 | KS10: ='لیست '!I80 -> 0 | KU10: ='لیست '!H81 -> 0 | KW10: ='لیست '!I81 -> 0 | KY10: ='لیست '!H82 -> 0 | LA10: ='لیست '!I82 -> 0 | LC10: ='لیست '!H83 -> 0 | LE10: ='لیست '!I83 -> 0 | LG10: ='لیست '!H84 -> 0 | LI10: ='لیست '!I84 -> 0 | LK10: ='لیست '!H85 -> 0 | LM10: ='لیست '!I85 -> 0 | LO10: ='لیست '!H86 -> 0 | LQ10: ='لیست '!I86 -> 0 | LS10: ='لیست '!H87 -> 0 | LU10: ='لیست '!I87 -> 0 | LW10: ='لیست '!H88 -> 0 | LY10: ='لیست '!I88 -> 0 | MA10: ='لیست '!H89 -> 0 | MC10: ='لیست '!I89 -> 0 | ME10: ='لیست '!H90 -> 0 | MG10: ='لیست '!I90 -> 0 | MI10: ='لیست '!H91 -> 0 | MK10: ='لیست '!I91 -> 0 | MM10: ='لیست '!H92 -> 0 | MO10: ='لیست '!I92 -> 0 | MQ10: ='لیست '!H93 -> 0 | MS10: ='لیست '!I93 -> 0 | MU10: ='لیست '!H94 -> 0 | MW10: ='لیست '!I94 -> 0 | MY10: ='لیست '!H95 -> 0 | NA10: ='لیست '!I95 -> 0 | NC10: ='لیست '!H96 -> 0 | NE10: ='لیست '!I96 -> 0 | NG10: ='لیست '!H97 -> 0 | NI10: ='لیست '!I97 -> 0 | NK10: ='لیست '!H98 -> 0 | NM10: ='لیست '!I98 -> 0 | NO10: ='لیست '!H99 -> 0 | NQ10: ='لیست '!I99 -> 0 | NS10: ='لیست '!H100 -> 0 | NU10: ='لیست '!I100 -> 0 | NW10: ='لیست '!H101 -> 0 | NY10: ='لیست '!I101 -> 0 | OA10: ='لیست '!H102 -> 0 | OC10: ='لیست '!I102 -> 0
C11: تکرار صنف | G11: تکرار صنف | K11: تکرار صنف | O11: تکرار صنف | S11: تکرار صنف | W11: تکرار صنف | AA11: تکرار صنف | AE11: تکرار صنف | AI11: تکرار صنف | AM11: تکرار صنف | AQ11: تکرار صنف | AU11: تکرار صنف | AY11: تکرار صنف | BC11: تکرار صنف | BG11: تکرار صنف | BK11: تکرار صنف | BO11: تکرار صنف | BS11: تکرار صنف | BW11: تکرار صنف | CA11: تکرار صنف | CE11: تکرار صنف | CI11: تکرار صنف | CM11: تکرار صنف | CQ11: تکرار صنف | CU11: تکرار صنف | CY11: تکرار صنف | DC11: تکرار صنف | DG11: تکرار صنف | DK11: تکرار صنف | DO11: تکرار صنف | DS11: تکرار صنف | DW11: تکرار صنف | EA11: تکرار صنف | EE11: تکرار صنف | EI11: تکرار صنف | EM11: تکرار صنف | EQ11: تکرار صنف | EU11: تکرار صنف | EY11: تکرار صنف | FC11: تکرار صنف | FG11: تکرار صنف | FK11: تکرار صنف | FO11: تکرار صنف | FS11: تکرار صنف | FW11: تکرار صنف | GA11: تکرار صنف | GE11: تکرار صنف | GI11: تکرار صنف | GM11: تکرار صنف | GQ11: تکرار صنف | GU11: تکرار صنف | GY11: تکرار صنف | HC11: تکرار صنف | HG11: تکرار صنف | HK11: تکرار صنف | HO11: تکرار صنف | HS11: تکرار صنف | HW11: تکرار صنف | IA11: تکرار صنف | IE11: تکرار صنف | II11: تکرار صنف | IM11: تکرار صنف | IQ11: تکرار صنف | IU11: تکرار صنف | IY11: تکرار صنف | JC11: تکرار صنف | JG11: تکرار صنف | JK11: تکرار صنف | JO11: تکرار صنف | JS11: تکرار صنف | JW11: تکرار صنف | KA11: تکرار صنف | KE11: تکرار صنف | KI11: تکرار صنف | KM11: تکرار صنف | KQ11: تکرار صنف | KU11: تکرار صنف | KY11: تکرار صنف | LC11: تکرار صنف | LG11: تکرار صنف | LK11: تکرار صنف | LO11: تکرار صنف | LS11: تکرار صنف | LW11: تکرار صنف | MA11: تکرار صنف | ME11: تکرار صنف | MI11: تکرار صنف | MM11: تکرار صنف | MQ11: تکرار صنف | MU11: تکرار صنف | MY11: تکرار صنف | NC11: تکرار صنف | NG11: تکرار صنف | NK11: تکرار صنف | NO11: تکرار صنف | NS11: تکرار صنف | NW11: تکرار صنف | OA11: تکرار صنف
A12: شماره | C12: 1 | F12: ='لیست '!BA5 -> 0 | G12: 2 | J12: ='لیست '!BA6 -> 0 | K12: 3 | N12: ='لیست '!BA7 -> 0 | O12: 4 | R12: ='لیست '!BA8 -> 0 | S12: 5 | V12: ='لیست '!BA9 -> 0 | W12: 6 | Z12: ='لیست '!BA10 -> 0 | AA12: 7 | AD12: ='لیست '!BA11 -> 0 | AE12: 8 | AH12: ='لیست '!BA12 -> 0 | AI12: 9 | AL12: ='لیست '!BA13 -> 0 | AM12: 10 | AP12: ='لیست '!BA14 -> 0 | AQ12: 11 | AT12: ='لیست '!BA15 -> 0 | AU12: 12 | AX12: ='لیست '!BA16 -> 0 | AY12: 13 | BB12: ='لیست '!BA17 -> 0 | BC12: 14 | BF12: ='لیست '!BA18 -> 0 | BG12: 15 | BJ12: ='لیست '!BA19 -> 0 | BK12: 16 | BN12: ='لیست '!BA20 -> 0 | BO12: 17 | BR12: ='لیست '!BA21 -> 0 | BS12: 18 | BV12: ='لیست '!BA22 -> 0 | BW12: 19 | BZ12: ='لیست '!BA23 -> 0 | CA12: 20 | CD12: ='لیست '!BA24 -> 0 | CE12: 21 | CH12: ='لیست '!BA25 -> 0 | CI12: 22 | CL12: ='لیست '!BA26 -> 0 | CM12: 23 | CP12: ='لیست '!BA27 -> 0 | CQ12: 24 | CT12: ='لیست '!BA28 -> 0 | CU12: 25 | CX12: ='لیست '!BA29 -> 0 | CY12: 26 | DB12: ='لیست '!BA30 -> 0 | DC12: 27 | DF12: ='لیست '!BA31 -> 0 | DG12: 28 | DJ12: ='لیست '!BA32 -> 0 | DK12: 29 | DN12: ='لیست '!BA33 -> 0 | DO12: 30 | DR12: ='لیست '!BA34 -> 0 | DS12: 31 | DV12: ='لیست '!BA35 -> 0 | DW12: 32 | DZ12: ='لیست '!BA36 -> 0 | EA12: 33 | ED12: ='لیست '!BA37 -> 0 | EE12: 34 | EH12: ='لیست '!BA38 -> 0 | EI12: 35 | EL12: ='لیست '!BA39 -> 0 | EM12: 36 | EP12: ='لیست '!BA40 -> 0 | EQ12: 37 | ET12: ='لیست '!BA41 -> 0 | EU12: 38 | EX12: ='لیست '!BA42 -> 0 | EY12: 39 | FB12: ='لیست '!BA43 -> 0 | FC12: 40 | FF12: ='لیست '!BA44 -> 0 | FG12: 41 | FJ12: ='لیست '!BA45 -> 0 | FK12: 42 | FN12: ='لیست '!BA46 -> 0 | FO12: 43 | FR12: ='لیست '!BA47 -> 0 | FS12: 44 | FV12: ='لیست '!BA48 -> 0 | FW12: 45 | FZ12: ='لیست '!BA49 -> 0 | GA12: 46 | GD12: ='لیست '!BA50 -> 0 | GE12: 47 | GH12: ='لیست '!BA51 -> 0 | GI12: 48 | GL12: ='لیست '!BA52 -> 0 | GM12: 49 | GP12: ='لیست '!BA53 -> 0 | GQ12: 50 | GT12: ='لیست '!BA54 -> 0 | GU12: 51 | GX12: ='لیست '!BA55 -> 0 | GY12: 52 | HB12: ='لیست '!BA56 -> 0 | HC12: 53 | HF12: ='لیست '!BA57 -> 0 | HG12: 54 | HJ12: ='لیست '!BA58 -> 0 | HK12: 55 | HN12: ='لیست '!BA59 -> 0 | HO12: 56 | HR12: ='لیست '!BA60 -> 0 | HS12: 57 | HV12: ='لیست '!BA61 -> 0 | HW12: 58 | HZ12: ='لیست '!BA62 -> 0 | IA12: 59 | ID12: ='لیست '!BA63 -> 0 | IE12: 60 | IH12: ='لیست '!BA64 -> 0 | II12: 61 | IL12: ='لیست '!BA65 -> 0 | IM12: 62 | IP12: ='لیست '!BA66 -> 0 | IQ12: 63 | IT12: ='لیست '!BA67 -> 0 | IU12: 64 | IX12: ='لیست '!BA68 -> 0 | IY12: 65 | JB12: ='لیست '!BA69 -> 0 | JC12: 66 | JF12: ='لیست '!BA70 -> 0 | JG12: 67 | JJ12: ='لیست '!BA71 -> 0 | JK12: 68 | JN12: ='لیست '!BA72 -> 0 | JO12: 69 | JR12: ='لیست '!BA73 -> 0 | JS12: 70 | JV12: ='لیست '!BA74 -> 0 | JW12: 71 | JZ12: ='لیست '!BA75 -> 0 | KA12: 72 | KD12: ='لیست '!BA76 -> 0 | KE12: 73 | KH12: ='لیست '!BA77 -> 0 | KI12: 74 | KL12: ='لیست '!BA78 -> 0 | KM12: 75 | KP12: ='لیست '!BA79 -> 0 | KQ12: 76 | KT12: ='لیست '!BA80 -> 0 | KU12: 77 | KX12: ='لیست '!BA81 -> 0 | KY12: 78 | LB12: ='لیست '!BA82 -> 0 | LC12: 79 | LF12: ='لیست '!BA83 -> 0 | LG12: 80 | LJ12: ='لیست '!BA84 -> 0 | LK12: 81 | LN12: ='لیست '!BA85 -> 0 | LO12: 82 | LR12: ='لیست '!BA86 -> 0 | LS12: 83 | LV12: ='لیست '!BA87 -> 0 | LW12: 84 | LZ12: ='لیست '!BA88 -> 0 | MA12: 85 | MD12: ='لیست '!BA89 -> 0 | ME12: 86 | MH12: ='لیست '!BA90 -> 0 | MI12: 87 | ML12: ='لیست '!BA91 -> 0 | MM12: 88 | MP12: ='لیست '!BA92 -> 0 | MQ12: 89 | MT12: ='لیست '!BA93 -> 0 | MU12: 90 | MX12: ='لیست '!BA94 -> 0 | MY12: 91 | NB12: ='لیست '!BA95 -> 0 | NC12: 92 | NF12: ='لیست '!BA96 -> 0 | NG12: 93 | NJ12: ='لیست '!BA97 -> 0 | NK12: 94 | NN12: ='لیست '!BA98 -> 0 | NO12: 95 | NR12: ='لیست '!BA99 -> 0 | NS12: 96 | NV12: ='لیست '!BA100 -> 0 | NW12: 97 | NZ12: ='لیست '!BA101 -> 0 | OA12: 98 | OD12: ='لیست '!BA102 -> 0
A13: شهرت | B13: اسم | C13: ='لیست '!B5 -> 0 | G13: ='لیست '!B6 -> 0 | K13: ='لیست '!B7 -> 0 | O13: ='لیست '!B8 -> 0 | S13: ='لیست '!B9 -> 0 | W13: ='لیست '!B10 -> 0 | AA13: ='لیست '!B11 -> 0 | AE13: ='لیست '!B12 -> 0 | AI13: ='لیست '!B13 -> 0 | AM13: ='لیست '!B14 -> 0 | AQ13: ='لیست '!B15 -> 0 | AU13: ='لیست '!B16 -> 0 | AY13: ='لیست '!B17 -> 0 | BC13: ='لیست '!B18 -> 0 | BG13: ='لیست '!B19 -> 0 | BK13: ='لیست '!B20 -> 0 | BO13: ='لیست '!B21 -> 0 | BS13: ='لیست '!B22 -> 0 | BW13: ='لیست '!B23 -> 0 | CA13: ='لیست '!B24 -> 0 | CE13: ='لیست '!B25 -> 0 | CI13: ='لیست '!B26 -> 0 | CM13: ='لیست '!B27 -> 0 | CQ13: ='لیست '!B28 -> 0 | CU13: ='لیست '!B29 -> 0 | CY13: ='لیست '!B30 -> 0 | DC13: ='لیست '!B31 -> 0 | DG13: ='لیست '!B32 -> 0 | DK13: ='لیست '!B33 -> 0 | DO13: ='لیست '!B34 -> 0 | DS13: ='لیست '!B35 -> 0 | DW13: ='لیست '!B36 -> 0 | EA13: ='لیست '!B37 -> 0 | EE13: ='لیست '!B38 -> 0 | EI13: ='لیست '!B39 -> 0 | EM13: ='لیست '!B40 -> 0 | EQ13: ='لیست '!B41 -> 0 | EU13: ='لیست '!B42 -> 0 | EY13: ='لیست '!B43 -> 0 | FC13: ='لیست '!B44 -> 0 | FG13: ='لیست '!B45 -> 0 | FK13: ='لیست '!B46 -> 0 | FO13: ='لیست '!B47 -> 0 | FS13: ='لیست '!B48 -> 0 | FW13: ='لیست '!B49 -> 0 | GA13: ='لیست '!B50 -> 0 | GE13: ='لیست '!B51 -> 0 | GI13: ='لیست '!B52 -> 0 | GM13: ='لیست '!B53 -> 0 | GQ13: ='لیست '!B54 -> 0 | GU13: ='لیست '!B55 -> 0 | GY13: ='لیست '!B56 -> 0 | HC13: ='لیست '!B57 -> 0 | HG13: ='لیست '!B58 -> 0 | HK13: ='لیست '!B59 -> 0 | HO13: ='لیست '!B60 -> 0 | HS13: ='لیست '!B61 -> 0 | HW13: ='لیست '!B62 -> 0 | IA13: ='لیست '!B63 -> 0 | IE13: ='لیست '!B64 -> 0 | II13: ='لیست '!B65 -> 0 | IM13: ='لیست '!B66 -> 0 | IQ13: ='لیست '!B67 -> 0 | IU13: ='لیست '!B68 -> 0 | IY13: ='لیست '!B69 -> 0 | JC13: ='لیست '!B70 -> 0 | JG13: ='لیست '!B71 -> 0 | JK13: ='لیست '!B72 -> 0 | JO13: ='لیست '!B73 -> 0 | JS13: ='لیست '!B74 -> 0 | JW13: ='لیست '!B75 -> 0 | KA13: ='لیست '!B76 -> 0 | KE13: ='لیست '!B77 -> 0 | KI13: ='لیست '!B78 -> 0 | KM13: ='لیست '!B79 -> 0 | KQ13: ='لیست '!B80 -> 0 | KU13: ='لیست '!B81 -> 0 | KY13: ='لیست '!B82 -> 0 | LC13: ='لیست '!B83 -> 0 | LG13: ='لیست '!B84 -> 0 | LK13: ='لیست '!B85 -> 0 | LO13: ='لیست '!B86 -> 0 | LS13: ='لیست '!B87 -> 0 | LW13: ='لیست '!B88 -> 0 | MA13: ='لیست '!B89 -> 0 | ME13: ='لیست '!B90 -> 0 | MI13: ='لیست '!B91 -> 0 | MM13: ='لیست '!B92 -> 0 | MQ13: ='لیست '!B93 -> 0 | MU13: ='لیست '!B94 -> 0 | MY13: ='لیست '!B95 -> 0 | NC13: ='لیست '!B96 -> 0 | NG13: ='لیست '!B97 -> 0 | NK13: ='لیست '!B98 -> 0 | NO13: ='لیست '!B99 -> 0 | NS13: ='لیست '!B100 -> 0 | NW13: ='لیست '!B101 -> 0 | OA13: ='لیست '!B102 -> 0
B14: نام پدر | C14: ='لیست '!C5 -> 0 | G14: ='لیست '!C6 -> 0 | K14: ='لیست '!C7 -> 0 | O14: ='لیست '!C8 -> 0 | S14: ='لیست '!C9 -> 0 | W14: ='لیست '!C10 -> 0 | AA14: ='لیست '!C11 -> 0 | AE14: ='لیست '!C12 -> 0 | AI14: ='لیست '!C13 -> 0 | AM14: ='لیست '!C14 -> 0 | AQ14: ='لیست '!C15 -> 0 | AU14: ='لیست '!C16 -> 0 | AY14: ='لیست '!C17 -> 0 | BC14: ='لیست '!C18 -> 0 | BG14: ='لیست '!C19 -> 0 | BK14: ='لیست '!C20 -> 0 | BO14: ='لیست '!C21 -> 0 | BS14: ='لیست '!C22 -> 0 | BW14: ='لیست '!C23 -> 0 | CA14: ='لیست '!C24 -> 0 | CE14: ='لیست '!C25 -> 0 | CI14: ='لیست '!C26 -> 0 | CM14: ='لیست '!C27 -> 0 | CQ14: ='لیست '!C28 -> 0 | CU14: ='لیست '!C29 -> 0 | CY14: ='لیست '!C30 -> 0 | DC14: ='لیست '!C31 -> 0 | DG14: ='لیست '!C32 -> 0 | DK14: ='لیست '!C33 -> 0 | DO14: ='لیست '!C34 -> 0 | DS14: ='لیست '!C35 -> 0 | DW14: ='لیست '!C36 -> 0 | EA14: ='لیست '!C37 -> 0 | EE14: ='لیست '!C38 -> 0 | EI14: ='لیست '!C39 -> 0 | EM14: ='لیست '!C40 -> 0 | EQ14: ='لیست '!C41 -> 0 | EU14: ='لیست '!C42 -> 0 | EY14: ='لیست '!C43 -> 0 | FC14: ='لیست '!C44 -> 0 | FG14: ='لیست '!C45 -> 0 | FK14: ='لیست '!C46 -> 0 | FO14: ='لیست '!C47 -> 0 | FS14: ='لیست '!C48 -> 0 | FW14: ='لیست '!C49 -> 0 | GA14: ='لیست '!C50 -> 0 | GE14: ='لیست '!C51 -> 0 | GI14: ='لیست '!C52 -> 0 | GM14: ='لیست '!C53 -> 0 | GQ14: ='لیست '!C54 -> 0 | GU14: ='لیست '!C55 -> 0 | GY14: ='لیست '!C56 -> 0 | HC14: ='لیست '!C57 -> 0 | HG14: ='لیست '!C58 -> 0 | HK14: ='لیست '!C59 -> 0 | HO14: ='لیست '!C60 -> 0 | HS14: ='لیست '!C61 -> 0 | HW14: ='لیست '!C62 -> 0 | IA14: ='لیست '!C63 -> 0 | IE14: ='لیست '!C64 -> 0 | II14: ='لیست '!C65 -> 0 | IM14: ='لیست '!C66 -> 0 | IQ14: ='لیست '!C67 -> 0 | IU14: ='لیست '!C68 -> 0 | IY14: ='لیست '!C69 -> 0 | JC14: ='لیست '!C70 -> 0 | JG14: ='لیست '!C71 -> 0 | JK14: ='لیست '!C72 -> 0 | JO14: ='لیست '!C73 -> 0 | JS14: ='لیست '!C74 -> 0 | JW14: ='لیست '!C75 -> 0 | KA14: ='لیست '!C76 -> 0 | KE14: ='لیست '!C77 -> 0 | KI14: ='لیست '!C78 -> 0 | KM14: ='لیست '!C79 -> 0 | KQ14: ='لیست '!C80 -> 0 | KU14: ='لیست '!C81 -> 0 | KY14: ='لیست '!C82 -> 0 | LC14: ='لیست '!C83 -> 0 | LG14: ='لیست '!C84 -> 0 | LK14: ='لیست '!C85 -> 0 | LO14: ='لیست '!C86 -> 0 | LS14: ='لیست '!C87 -> 0 | LW14: ='لیست '!C88 -> 0 | MA14: ='لیست '!C89 -> 0 | ME14: ='لیست '!C90 -> 0 | MI14: ='لیست '!C91 -> 0 | MM14: ='لیست '!C92 -> 0 | MQ14: ='لیست '!C93 -> 0 | MU14: ='لیست '!C94 -> 0 | MY14: ='لیست '!C95 -> 0 | NC14: ='لیست '!C96 -> 0 | NG14: ='لیست '!C97 -> 0 | NK14: ='لیست '!C98 -> 0 | NO14: ='لیست '!C99 -> 0 | NS14: ='لیست '!C100 -> 0 | NW14: ='لیست '!C101 -> 0 | OA14: ='لیست '!C102 -> 0 | OG14: استادان محترم: برای درج هر نوع معلومات تحریری به شیټ(لیست) مراجعه نماید این جدول فقط برای پرنت میباشد. اپدیت کننده: عزت الله عابد استاد لېسه عالي ګل پاچا الفت حوزه دوازهم تعلیمی - کابل شماره وتسپ: 0780442278
B15: نام پدر کلان | C15: ='لیست '!D5 -> 0 | G15: ='لیست '!D6 -> 0 | K15: ='لیست '!D7 -> 0 | O15: ='لیست '!D8 -> 0 | S15: ='لیست '!D9 -> 0 | W15: ='لیست '!D10 -> 0 | AA15: ='لیست '!D11 -> 0 | AE15: ='لیست '!D12 -> 0 | AI15: ='لیست '!D13 -> 0 | AM15: ='لیست '!D14 -> 0 | AQ15: ='لیست '!D15 -> 0 | AU15: ='لیست '!D16 -> 0 | AY15: ='لیست '!D17 -> 0 | BC15: ='لیست '!D18 -> 0 | BG15: ='لیست '!D19 -> 0 | BK15: ='لیست '!D20 -> 0 | BO15: ='لیست '!D21 -> 0 | BS15: ='لیست '!D22 -> 0 | BW15: ='لیست '!D23 -> 0 | CA15: ='لیست '!D24 -> 0 | CE15: ='لیست '!D25 -> 0 | CI15: ='لیست '!D26 -> 0 | CM15: ='لیست '!D27 -> 0 | CQ15: ='لیست '!D28 -> 0 | CU15: ='لیست '!D29 -> 0 | CY15: ='لیست '!D30 -> 0 | DC15: ='لیست '!D31 -> 0 | DG15: ='لیست '!D32 -> 0 | DK15: ='لیست '!D33 -> 0 | DO15: ='لیست '!D34 -> 0 | DS15: ='لیست '!D35 -> 0 | DW15: ='لیست '!D36 -> 0 | EA15: ='لیست '!D37 -> 0 | EE15: ='لیست '!D38 -> 0 | EI15: ='لیست '!D39 -> 0 | EM15: ='لیست '!D40 -> 0 | EQ15: ='لیست '!D41 -> 0 | EU15: ='لیست '!D42 -> 0 | EY15: ='لیست '!D43 -> 0 | FC15: ='لیست '!D44 -> 0 | FG15: ='لیست '!D45 -> 0 | FK15: ='لیست '!D46 -> 0 | FO15: ='لیست '!D47 -> 0 | FS15: ='لیست '!D48 -> 0 | FW15: ='لیست '!D49 -> 0 | GA15: ='لیست '!D50 -> 0 | GE15: ='لیست '!D51 -> 0 | GI15: ='لیست '!D52 -> 0 | GM15: ='لیست '!D53 -> 0 | GQ15: ='لیست '!D54 -> 0 | GU15: ='لیست '!D55 -> 0 | GY15: ='لیست '!D56 -> 0 | HC15: ='لیست '!D57 -> 0 | HG15: ='لیست '!D58 -> 0 | HK15: ='لیست '!D59 -> 0 | HO15: ='لیست '!D60 -> 0 | HS15: ='لیست '!D61 -> 0 | HW15: ='لیست '!D62 -> 0 | IA15: ='لیست '!D63 -> 0 | IE15: ='لیست '!D64 -> 0 | II15: ='لیست '!D65 -> 0 | IM15: ='لیست '!D66 -> 0 | IQ15: ='لیست '!D67 -> 0 | IU15: ='لیست '!D68 -> 0 | IY15: ='لیست '!D69 -> 0 | JC15: ='لیست '!D70 -> 0 | JG15: ='لیست '!D71 -> 0 | JK15: ='لیست '!D72 -> 0 | JO15: ='لیست '!D73 -> 0 | JS15: ='لیست '!D74 -> 0 | JW15: ='لیست '!D75 -> 0 | KA15: ='لیست '!D76 -> 0 | KE15: ='لیست '!D77 -> 0 | KI15: ='لیست '!D78 -> 0 | KM15: ='لیست '!D79 -> 0 | KQ15: ='لیست '!D80 -> 0 | KU15: ='لیست '!D81 -> 0 | KY15: ='لیست '!D82 -> 0 | LC15: ='لیست '!D83 -> 0 | LG15: ='لیست '!D84 -> 0 | LK15: ='لیست '!D85 -> 0 | LO15: ='لیست '!D86 -> 0 | LS15: ='لیست '!D87 -> 0 | LW15: ='لیست '!D88 -> 0 | MA15: ='لیست '!D89 -> 0 | ME15: ='لیست '!D90 -> 0 | MI15: ='لیست '!D91 -> 0 | MM15: ='لیست '!D92 -> 0 | MQ15: ='لیست '!D93 -> 0 | MU15: ='لیست '!D94 -> 0 | MY15: ='لیست '!D95 -> 0 | NC15: ='لیست '!D96 -> 0 | NG15: ='لیست '!D97 -> 0 | NK15: ='لیست '!D98 -> 0 | NO15: ='لیست '!D99 -> 0 | NS15: ='لیست '!D100 -> 0 | NW15: ='لیست '!D101 -> 0 | OA15: ='لیست '!D102 -> 0
A16: نمبر اساس | C16: ='لیست '!E5 -> 0 | G16: ='لیست '!E6 -> 0 | K16: ='لیست '!E7 -> 0 | O16: ='لیست '!E8 -> 0 | S16: ='لیست '!E9 -> 0 | W16: ='لیست '!E10 -> 0 | AA16: ='لیست '!E11 -> 0 | AE16: ='لیست '!E12 -> 0 | AI16: ='لیست '!E13 -> 0 | AM16: ='لیست '!E14 -> 0 | AQ16: ='لیست '!E15 -> 0 | AU16: ='لیست '!E16 -> 0 | AY16: ='لیست '!E17 -> 0 | BC16: ='لیست '!E18 -> 0 | BG16: ='لیست '!E19 -> 0 | BK16: ='لیست '!E20 -> 0 | BO16: ='لیست '!E21 -> 0 | BS16: ='لیست '!E22 -> 0 | BW16: ='لیست '!E23 -> 0 | CA16: ='لیست '!E24 -> 0 | CE16: ='لیست '!E25 -> 0 | CI16: ='لیست '!E26 -> 0 | CM16: ='لیست '!E27 -> 0 | CQ16: ='لیست '!E28 -> 0 | CU16: ='لیست '!E29 -> 0 | CY16: ='لیست '!E30 -> 0 | DC16: ='لیست '!E31 -> 0 | DG16: ='لیست '!E32 -> 0 | DK16: ='لیست '!E33 -> 0 | DO16: ='لیست '!E34 -> 0 | DS16: ='لیست '!E35 -> 0 | DW16: ='لیست '!E36 -> 0 | EA16: ='لیست '!E37 -> 0 | EE16: ='لیست '!E38 -> 0 | EI16: ='لیست '!E39 -> 0 | EM16: ='لیست '!E40 -> 0 | EQ16: ='لیست '!E41 -> 0 | EU16: ='لیست '!E42 -> 0 | EY16: ='لیست '!E43 -> 0 | FC16: ='لیست '!E44 -> 0 | FG16: ='لیست '!E45 -> 0 | FK16: ='لیست '!E46 -> 0 | FO16: ='لیست '!E47 -> 0 | FS16: ='لیست '!E48 -> 0 | FW16: ='لیست '!E49 -> 0 | GA16: ='لیست '!E50 -> 0 | GE16: ='لیست '!E51 -> 0 | GI16: ='لیست '!E52 -> 0 | GM16: ='لیست '!E53 -> 0 | GQ16: ='لیست '!E54 -> 0 | GU16: ='لیست '!E55 -> 0 | GY16: ='لیست '!E56 -> 0 | HC16: ='لیست '!E57 -> 0 | HG16: ='لیست '!E58 -> 0 | HK16: ='لیست '!E59 -> 0 | HO16: ='لیست '!E60 -> 0 | HS16: ='لیست '!E61 -> 0 | HW16: ='لیست '!E62 -> 0 | IA16: ='لیست '!E63 -> 0 | IE16: ='لیست '!E64 -> 0 | II16: ='لیست '!E65 -> 0 | IM16: ='لیست '!E66 -> 0 | IQ16: ='لیست '!E67 -> 0 | IU16: ='لیست '!E68 -> 0 | IY16: ='لیست '!E69 -> 0 | JC16: ='لیست '!E70 -> 0 | JG16: ='لیست '!E71 -> 0 | JK16: ='لیست '!E72 -> 0 | JO16: ='لیست '!E73 -> 0 | JS16: ='لیست '!E74 -> 0 | JW16: ='لیست '!E75 -> 0 | KA16: ='لیست '!E76 -> 0 | KE16: ='لیست '!E77 -> 0 | KI16: ='لیست '!E78 -> 0 | KM16: ='لیست '!E79 -> 0 | KQ16: ='لیست '!E80 -> 0 | KU16: ='لیست '!E81 -> 0 | KY16: ='لیست '!E82 -> 0 | LC16: ='لیست '!E83 -> 0 | LG16: ='لیست '!E84 -> 0 | LK16: ='لیست '!E85 -> 0 | LO16: ='لیست '!E86 -> 0 | LS16: ='لیست '!E87 -> 0 | LW16: ='لیست '!E88 -> 0 | MA16: ='لیست '!E89 -> 0 | ME16: ='لیست '!E90 -> 0 | MI16: ='لیست '!E91 -> 0 | MM16: ='لیست '!E92 -> 0 | MQ16: ='لیست '!E93 -> 0 | MU16: ='لیست '!E94 -> 0 | MY16: ='لیست '!E95 -> 0 | NC16: ='لیست '!E96 -> 0 | NG16: ='لیست '!E97 -> 0 | NK16: ='لیست '!E98 -> 0 | NO16: ='لیست '!E99 -> 0 | NS16: ='لیست '!E100 -> 0 | NW16: ='لیست '!E101 -> 0 | OA16: ='لیست '!E102 -> 0
A17: نمبر تذکره | C17: ='لیست '!F5 -> 0 | G17: ='لیست '!F6 -> 0 | K17: ='لیست '!F7 -> 0 | O17: ='لیست '!F8 -> 0 | S17: ='لیست '!F9 -> 0 | W17: ='لیست '!F10 -> 0 | AA17: ='لیست '!F11 -> 0 | AE17: ='لیست '!F12 -> 0 | AI17: ='لیست '!F13 -> 0 | AM17: ='لیست '!F14 -> 0 | AQ17: ='لیست '!F15 -> 0 | AU17: ='لیست '!F16 -> 0 | AY17: ='لیست '!F17 -> 0 | BC17: ='لیست '!F18 -> 0 | BG17: ='لیست '!F19 -> 0 | BK17: ='لیست '!F20 -> 0 | BO17: ='لیست '!F21 -> 0 | BS17: ='لیست '!F22 -> 0 | BW17: ='لیست '!F23 -> 0 | CA17: ='لیست '!F24 -> 0 | CE17: ='لیست '!F25 -> 0 | CI17: ='لیست '!F26 -> 0 | CM17: ='لیست '!F27 -> 0 | CQ17: ='لیست '!F28 -> 0 | CU17: ='لیست '!F29 -> 0 | CY17: ='لیست '!F30 -> 0 | DC17: ='لیست '!F31 -> 0 | DG17: ='لیست '!F32 -> 0 | DK17: ='لیست '!F33 -> 0 | DO17: ='لیست '!F34 -> 0 | DS17: ='لیست '!F35 -> 0 | DW17: ='لیست '!F36 -> 0 | EA17: ='لیست '!F37 -> 0 | EE17: ='لیست '!F38 -> 0 | EI17: ='لیست '!F39 -> 0 | EM17: ='لیست '!F40 -> 0 | EQ17: ='لیست '!F41 -> 0 | EU17: ='لیست '!F42 -> 0 | EY17: ='لیست '!F43 -> 0 | FC17: ='لیست '!F44 -> 0 | FG17: ='لیست '!F45 -> 0 | FK17: ='لیست '!F46 -> 0 | FO17: ='لیست '!F47 -> 0 | FS17: ='لیست '!F48 -> 0 | FW17: ='لیست '!F49 -> 0 | GA17: ='لیست '!F50 -> 0 | GE17: ='لیست '!F51 -> 0 | GI17: ='لیست '!F52 -> 0 | GM17: ='لیست '!F53 -> 0 | GQ17: ='لیست '!F54 -> 0 | GU17: ='لیست '!F55 -> 0 | GY17: ='لیست '!F56 -> 0 | HC17: ='لیست '!F57 -> 0 | HG17: ='لیست '!F58 -> 0 | HK17: ='لیست '!F59 -> 0 | HO17: ='لیست '!F60 -> 0 | HS17: ='لیست '!F61 -> 0 | HW17: ='لیست '!F62 -> 0 | IA17: ='لیست '!F63 -> 0 | IE17: ='لیست '!F64 -> 0 | II17: ='لیست '!F65 -> 0 | IM17: ='لیست '!F66 -> 0 | IQ17: ='لیست '!F67 -> 0 | IU17: ='لیست '!F68 -> 0 | IY17: ='لیست '!F69 -> 0 | JC17: ='لیست '!F70 -> 0 | JG17: ='لیست '!F71 -> 0 | JK17: ='لیست '!F72 -> 0 | JO17: ='لیست '!F73 -> 0 | JS17: ='لیست '!F74 -> 0 | JW17: ='لیست '!F75 -> 0 | KA17: ='لیست '!F76 -> 0 | KE17: ='لیست '!F77 -> 0 | KI17: ='لیست '!F78 -> 0 | KM17: ='لیست '!F79 -> 0 | KQ17: ='لیست '!F80 -> 0 | KU17: ='لیست '!F81 -> 0 | KY17: ='لیست '!F82 -> 0 | LC17: ='لیست '!F83 -> 0 | LG17: ='لیست '!F84 -> 0 | LK17: ='لیست '!F85 -> 0 | LO17: ='لیست '!F86 -> 0 | LS17: ='لیست '!F87 -> 0 | LW17: ='لیست '!F88 -> 0 | MA17: ='لیست '!F89 -> 0 | ME17: ='لیست '!F90 -> 0 | MI17: ='لیست '!F91 -> 0 | MM17: ='لیست '!F92 -> 0 | MQ17: ='لیست '!F93 -> 0 | MU17: ='لیست '!F94 -> 0 | MY17: ='لیست '!F95 -> 0 | NC17: ='لیست '!F96 -> 0 | NG17: ='لیست '!F97 -> 0 | NK17: ='لیست '!F98 -> 0 | NO17: ='لیست '!F99 -> 0 | NS17: ='لیست '!F100 -> 0 | NW17: ='لیست '!F101 -> 0 | OA17: ='لیست '!F102 -> 0
C18: چهارونیم ماهه | D18: سالانه | E18: نمرات نهائی | G18: چهارونیم ماهه | H18: سالانه | I18: نمرات نهائی | K18: چهارونیم ماهه | L18: سالانه | M18: نمرات نهائی | O18: چهارونیم ماهه | P18: سالانه | Q18: نمرات نهائی | S18: چهارونیم ماهه | T18: سالانه | U18: نمرات نهائی | W18: چهارونیم ماهه | X18: سالانه | Y18: نمرات نهائی | AA18: چهارونیم ماهه | AB18: سالانه | AC18: نمرات نهائی | AE18: چهارونیم ماهه | AF18: سالانه | AG18: نمرات نهائی | AI18: چهارونیم ماهه | AJ18: سالانه | AK18: نمرات نهائی | AM18: چهارونیم ماهه | AN18: سالانه | AO18: نمرات نهائی | AQ18: چهارونیم ماهه | AR18: سالانه | AS18: نمرات نهائی | AU18: چهارونیم ماهه | AV18: سالانه | AW18: نمرات نهائی | AY18: چهارونیم ماهه | AZ18: سالانه | BA18: نمرات نهائی | BC18: چهارونیم ماهه | BD18: سالانه | BE18: نمرات نهائی | BG18: چهارونیم ماهه | BH18: سالانه | BI18: نمرات نهائی | BK18: چهارونیم ماهه | BL18: سالانه | BM18: نمرات نهائی | BO18: چهارونیم ماهه | BP18: سالانه | BQ18: نمرات نهائی | BS18: چهارونیم ماهه | BT18: سالانه | BU18: نمرات نهائی | BW18: چهارونیم ماهه | BX18: سالانه | BY18: نمرات نهائی | CA18: چهارونیم ماهه | CB18: سالانه | CC18: نمرات نهائی | CE18: چهارونیم ماهه | CF18: سالانه | CG18: نمرات نهائی | CI18: چهارونیم ماهه | CJ18: سالانه | CK18: نمرات نهائی | CM18: چهارونیم ماهه | CN18: سالانه | CO18: نمرات نهائی | CQ18: چهارونیم ماهه | CR18: سالانه | CS18: نمرات نهائی | CU18: چهارونیم ماهه | CV18: سالانه | CW18: نمرات نهائی | CY18: چهارونیم ماهه | CZ18: سالانه | DA18: نمرات نهائی | DC18: چهارونیم ماهه | DD18: سالانه | DE18: نمرات نهائی | DG18: چهارونیم ماهه | DH18: سالانه | DI18: نمرات نهائی | DK18: چهارونیم ماهه | DL18: سالانه | DM18: نمرات نهائی | DO18: چهارونیم ماهه | DP18: سالانه | DQ18: نمرات نهائی | DS18: چهارونیم ماهه | DT18: سالانه | DU18: نمرات نهائی | DW18: چهارونیم ماهه | DX18: سالانه | DY18: نمرات نهائی | EA18: چهارونیم ماهه | EB18: سالانه | EC18: نمرات نهائی | EE18: چهارونیم ماهه | EF18: سالانه | EG18: نمرات نهائی | EI18: چهارونیم ماهه | EJ18: سالانه | EK18: نمرات نهائی | EM18: چهارونیم ماهه | EN18: سالانه | EO18: نمرات نهائی | EQ18: چهارونیم ماهه | ER18: سالانه | ES18: نمرات نهائی | EU18: چهارونیم ماهه | EV18: سالانه | EW18: نمرات نهائی | EY18: چهارونیم ماهه | EZ18: سالانه | FA18: نمرات نهائی | FC18: چهارونیم ماهه | FD18: سالانه | FE18: نمرات نهائی | FG18: چهارونیم ماهه | FH18: سالانه | FI18: نمرات نهائی | FK18: چهارونیم ماهه | FL18: سالانه | FM18: نمرات نهائی | FO18: چهارونیم ماهه | FP18: سالانه | FQ18: نمرات نهائی | FS18: چهارونیم ماهه | FT18: سالانه | FU18: نمرات نهائی | FW18: چهارونیم ماهه | FX18: سالانه | FY18: نمرات نهائی | GA18: چهارونیم ماهه | GB18: سالانه | GC18: نمرات نهائی | GE18: چهارونیم ماهه | GF18: سالانه | GG18: نمرات نهائی | GI18: چهارونیم ماهه | GJ18: سالانه | GK18: نمرات نهائی | GM18: چهارونیم ماهه | GN18: سالانه | GO18: نمرات نهائی | GQ18: چهارونیم ماهه | GR18: سالانه | GS18: نمرات نهائی | GU18: چهارونیم ماهه | GV18: سالانه | GW18: نمرات نهائی | GY18: چهارونیم ماهه | GZ18: سالانه | HA18: نمرات نهائی | HC18: چهارونیم ماهه | HD18: سالانه | HE18: نمرات نهائی | HG18: چهارونیم ماهه | HH18: سالانه | HI18: نمرات نهائی | HK18: چهارونیم ماهه | HL18: سالانه | HM18: نمرات نهائی | HO18: چهارونیم ماهه | HP18: سالانه | HQ18: نمرات نهائی | HS18: چهارونیم ماهه | HT18: سالانه | HU18: نمرات نهائی | HW18: چهارونیم ماهه | HX18: سالانه | HY18: نمرات نهائی | IA18: چهارونیم ماهه | IB18: سالانه | IC18: نمرات نهائی | IE18: چهارونیم ماهه | IF18: سالانه | IG18: نمرات نهائی | II18: چهارونیم ماهه | IJ18: سالانه | IK18: نمرات نهائی | IM18: چهارونیم ماهه | IN18: سالانه | IO18: نمرات نهائی | IQ18: چهارونیم ماهه | IR18: سالانه | IS18: نمرات نهائی | IU18: چهارونیم ماهه | IV18: سالانه | IW18: نمرات نهائی | IY18: چهارونیم ماهه | IZ18: سالانه | JA18: نمرات نهائی | JC18: چهارونیم ماهه | JD18: سالانه | JE18: نمرات نهائی | JG18: چهارونیم ماهه | JH18: سالانه | JI18: نمرات نهائی | JK18: چهارونیم ماهه | JL18: سالانه | JM18: نمرات نهائی | JO18: چهارونیم ماهه | JP18: سالانه | JQ18: نمرات نهائی | JS18: چهارونیم ماهه | JT18: سالانه | JU18: نمرات نهائی | JW18: چهارونیم ماهه | JX18: سالانه | JY18: نمرات نهائی | KA18: چهارونیم ماهه | KB18: سالانه | KC18: نمرات نهائی | KE18: چهارونیم ماهه | KF18: سالانه | KG18: نمرات نهائی | KI18: چهارونیم ماهه | KJ18: سالانه | KK18: نمرات نهائی | KM18: چهارونیم ماهه | KN18: سالانه | KO18: نمرات نهائی | KQ18: چهارونیم ماهه | KR18: سالانه | KS18: نمرات نهائی | KU18: چهارونیم ماهه | KV18: سالانه | KW18: نمرات نهائی | KY18: چهارونیم ماهه | KZ18: سالانه | LA18: نمرات نهائی | LC18: چهارونیم ماهه | LD18: سالانه | LE18: نمرات نهائی | LG18: چهارونیم ماهه | LH18: سالانه | LI18: نمرات نهائی | LK18: چهارونیم ماهه | LL18: سالانه | LM18: نمرات نهائی | LO18: چهارونیم ماهه | LP18: سالانه | LQ18: نمرات نهائی | LS18: چهارونیم ماهه | LT18: سالانه | LU18: نمرات نهائی | LW18: چهارونیم ماهه | LX18: سالانه | LY18: نمرات نهائی | MA18: چهارونیم ماهه | MB18: سالانه | MC18: نمرات نهائی | ME18: چهارونیم ماهه | MF18: سالانه | MG18: نمرات نهائی | MI18: چهارونیم ماهه | MJ18: سالانه | MK18: نمرات نهائی | MM18: چهارونیم ماهه | MN18: سالانه | MO18: نمرات نهائی | MQ18: چهارونیم ماهه | MR18: سالانه | MS18: نمرات نهائی | MU18: چهارونیم ماهه | MV18: سالانه | MW18: نمرات نهائی | MY18: چهارونیم ماهه | MZ18: سالانه | NA18: نمرات نهائی | NC18: چهارونیم ماهه | ND18: سالانه | NE18: نمرات نهائی | NG18: چهارونیم ماهه | NH18: سالانه | NI18: نمرات نهائی | NK18: چهارونیم ماهه | NL18: سالانه | NM18: نمرات نهائی | NO18: چهارونیم ماهه | NP18: سالانه | NQ18: نمرات نهائی | NS18: چهارونیم ماهه | NT18: سالانه | NU18: نمرات نهائی | NW18: چهارونیم ماهه | NX18: سالانه | NY18: نمرات نهائی | OA18: چهارونیم ماهه | OB18: سالانه | OC18: نمرات نهائی
